<?xml version="1.0" ?>
<!-- =================================================================================== -->
<!-- |    This document was autogenerated by xacro from indy.urdf.xacro                | -->
<!-- |    EDITING THIS FILE BY HAND IS NOT RECOMMENDED                                 | -->
<!-- =================================================================================== -->
<robot name="indy">
  <material name="black">
    <color rgba="0.0 0.0 0.0 1.0"/>
  </material>
  <material name="blue">
    <color rgba="0.0 0.0 0.8 1.0"/>
  </material>
  <material name="green">
    <color rgba="0.0 0.8 0.0 1.0"/>
  </material>
  <material name="icon_green">
    <color rgba="0.596078431372549 0.7764705882352941 0.3843137254901961 1.0"/>
  </material>
  <material name="icon_grey">
    <color rgba="0.2 0.2 0.2 1.0"/>
  </material>
  <material name="indy_white">
    <color rgba="0.8941176470588236 0.8941176470588236 0.8941176470588236 1.0"/>
  </material>
  <material name="grey">
    <color rgba="0.2 0.2 0.2 1.0"/>
  </material>
  <material name="orange">
    <color rgba="1.0 0.4235294117647059 0.0392156862745098 1.0"/>
  </material>
  <material name="brown">
    <color rgba="0.8705882352941177 0.8117647058823529 0.7647058823529411 1.0"/>
  </material>
  <material name="red">
    <color rgba="0.8 0.0 0.0 1.0"/>
  </material>
  <material name="white">
    <color rgba="1.0 1.0 1.0 1.0"/>
  </material>
  <material name="metal">
    <color rgba="0.768627450980392 0.749019607843137 0.729411764705882 1"/>
  </material>
  <material name="metal_grey">
    <color rgba="0.501960784313725 0.501960784313725 0.501960784313725 1"/>
  </material>
  <material name="metal_white">
    <color rgba="0.866666666666667 0.866666666666667 0.890196078431373 1"/>
  </material>
  <link name="world"/>
  <link name="link0">
    <visual>
      <origin rpy="0 0 0" xyz="0 0 0"/>
      <geometry>
        <mesh filename="file:///home/user/indy-ros/src/indy_description/meshes/indy12_v2/visual/Indy12_v2_0.stl"/>
      </geometry>
      <material name="indy_white"/>
    </visual>
    <collision>
      <origin rpy="0 0 0" xyz="0 0 0"/>
      <geometry>
        <mesh filename="file:///home/user/indy-ros/src/indy_description/meshes/indy12_v2/collision/Indy12_v2_0.stl"/>
      </geometry>
    </collision>
    <inertial>
      <mass value="2.56262283"/>
      <origin rpy="0 0 0" xyz="-0.00258732                             0.0                             0.03670771"/>
      <inertia ixx="0.01579442" ixy="1.182e-05" ixz="-0.00035039" iyy="0.01654858" iyz="-1.67e-06" izz="0.0212035"/>
    </inertial>
  </link>
  <link name="link1">
    <visual>
      <origin rpy="0 0 0" xyz="0 0 0"/>
      <geometry>
        <mesh filename="file:///home/user/indy-ros/src/indy_description/meshes/indy12_v2/visual/Indy12_v2_1.stl"/>
      </geometry>
      <material name="indy_white"/>
    </visual>
    <collision>
      <origin rpy="0 0 0" xyz="0 0 0"/>
      <geometry>
        <mesh filename="file:///home/user/indy-ros/src/indy_description/meshes/indy12_v2/collision/Indy12_v2_1.stl"/>
      </geometry>
    </collision>
    <inertial>
      <mass value="23.04941339"/>
      <origin rpy="0 0 0" xyz="0.00091757                             -0.04560974                             0.17670678"/>
      <inertia ixx="1.07131491" ixy="-0.00088608" ixz="0.00373079" iyy="0.9757198" iyz="-0.27757611" izz="0.15642641"/>
    </inertial>
  </link>
  <link name="link2">
    <visual>
      <origin rpy="0 0 0" xyz="0 0 0"/>
      <geometry>
        <mesh filename="file:///home/user/indy-ros/src/indy_description/meshes/indy12_v2/visual/Indy12_v2_2.stl"/>
      </geometry>
      <material name="indy_white"/>
    </visual>
    <collision>
      <origin rpy="0 0 0" xyz="0 0 0"/>
      <geometry>
        <mesh filename="file:///home/user/indy-ros/src/indy_description/meshes/indy12_v2/collision/Indy12_v2_2.stl"/>
      </geometry>
    </collision>
    <inertial>
      <mass value="13.86898329"/>
      <origin rpy="0 0 0" xyz="0.41245408                             -1.45e-06                             0.05902447"/>
      <inertia ixx="0.13467172" ixy="-2.79e-06" ixz="0.21911594" iyy="3.33493355" iyz="-6.26e-06" izz="3.25250492"/>
    </inertial>
  </link>
  <link name="link3">
    <visual>
      <origin rpy="0 0 0" xyz="0 0 0"/>
      <geometry>
        <mesh filename="file:///home/user/indy-ros/src/indy_description/meshes/indy12_v2/visual/Indy12_v2_3.stl"/>
      </geometry>
      <material name="indy_white"/>
    </visual>
    <collision>
      <origin rpy="0 0 0" xyz="0 0 0"/>
      <geometry>
        <mesh filename="file:///home/user/indy-ros/src/indy_description/meshes/indy12_v2/collision/Indy12_v2_3.stl"/>
      </geometry>
    </collision>
    <inertial>
      <mass value="4.33211778"/>
      <origin rpy="0 0 0" xyz="0.00010688                             -0.11279641                             -0.09952194"/>
      <inertia ixx="0.12705385" ixy="-7.126e-05" ixz="-5.316e-05" iyy="0.05350425" iyz="0.05251141" izz="0.08353879"/>
    </inertial>
  </link>
  <link name="link4">
    <visual>
      <origin rpy="0 0 0" xyz="0 0 0"/>
      <geometry>
        <mesh filename="file:///home/user/indy-ros/src/indy_description/meshes/indy12_v2/visual/Indy12_v2_4.stl"/>
      </geometry>
      <material name="indy_white"/>
    </visual>
    <collision>
      <origin rpy="0 0 0" xyz="0 0 0"/>
      <geometry>
        <mesh filename="file:///home/user/indy-ros/src/indy_description/meshes/indy12_v2/collision/Indy12_v2_4.stl"/>
      </geometry>
    </collision>
    <inertial>
      <mass value="5.29001581"/>
      <origin rpy="0 0 0" xyz="-3.298e-05                             -0.05026763                             0.26334634"/>
      <inertia ixx="0.49421792" ixy="9.67e-06" ixz="-6.517e-05" iyy="0.47039115" iyz="-0.0957018" izz="0.03440872"/>
    </inertial>
  </link>
  <link name="link5">
    <visual>
      <origin rpy="0 0 0" xyz="0 0 0"/>
      <geometry>
        <mesh filename="file:///home/user/indy-ros/src/indy_description/meshes/indy12_v2/visual/Indy12_v2_5.stl"/>
      </geometry>
      <material name="indy_white"/>
    </visual>
    <collision>
      <origin rpy="0 0 0" xyz="0 0 0"/>
      <geometry>
        <mesh filename="file:///home/user/indy-ros/src/indy_description/meshes/indy12_v2/collision/Indy12_v2_5.stl"/>
      </geometry>
    </collision>
    <inertial>
      <mass value="3.54429783"/>
      <origin rpy="0 0 0" xyz="0.0001457                             -0.02035115                             0.07381123"/>
      <inertia ixx="0.0302587" ixy="-9.21e-06" ixz="4.266e-05" iyy="0.02534867" iyz="-0.00570954" izz="0.01049163"/>
    </inertial>
  </link>
  <link name="link6">
    <visual>
      <origin rpy="0 0 0" xyz="0 0 0"/>
      <geometry>
        <mesh filename="file:///home/user/indy-ros/src/indy_description/meshes/indy12_v2/visual/Indy12_v2_6.stl"/>
      </geometry>
      <material name="indy_white"/>
    </visual>
    <collision>
      <origin rpy="0 0 0" xyz="0 0 0"/>
      <geometry>
        <mesh filename="file:///home/user/indy-ros/src/indy_description/meshes/indy12_v2/collision/Indy12_v2_6.stl"/>
      </geometry>
    </collision>
    <inertial>
      <mass value="3.6323592"/>
      <origin rpy="0 0 0" xyz="-0.00362661                             -0.00287313                             -0.00146223"/>
      <inertia ixx="0.02296417" ixy="-5.3e-07" ixz="0.00095428" iyy="0.02294874" iyz="0.00075929" izz="0.01036532"/>
    </inertial>
  </link>
  <link name="tcp"/>
  <joint name="global" type="fixed">
    <origin rpy="0 0 0" xyz="0 0 0"/>
    <parent link="world"/>
    <child link="link0"/>
  </joint>
  <joint name="joint0" type="revolute">
    <parent link="link0"/>
    <child link="link1"/>
    <origin rpy="0                         0                         0" xyz="0                          0                          0.083"/>
    <axis xyz="0 0 1"/>
    <dynamics damping="0.1" friction="10.0"/>
    <limit effort="431.97" lower="-3.0543261909900767" upper="3.0543261909900767" velocity="2.0943951023931953"/>
  </joint>
  <joint name="joint1" type="revolute">
    <parent link="link1"/>
    <child link="link2"/>
    <origin rpy="1.570796327                         -1.570796327                         0" xyz="0                          -0.137                          0.2675"/>
    <axis xyz="0 0 1"/>
    <dynamics damping="0.1" friction="10.0"/>
    <limit effort="431.97" lower="-3.0543261909900767" upper="3.0543261909900767" velocity="2.0943951023931953"/>
  </joint>
  <joint name="joint2" type="revolute">
    <parent link="link2"/>
    <child link="link3"/>
    <origin rpy="0                         0                         1.570796327" xyz="0.652                          0                          -0.0205"/>
    <axis xyz="0 0 1"/>
    <dynamics damping="0.1" friction="10.0"/>
    <limit effort="197.23" lower="-3.0543261909900767" upper="3.0543261909900767" velocity="2.0943951023931953"/>
  </joint>
  <joint name="joint3" type="revolute">
    <parent link="link3"/>
    <child link="link4"/>
    <origin rpy="-1.570796327                         0                         3.14159265" xyz="0                          -0.21                          -0.10595"/>
    <axis xyz="0 0 1"/>
    <dynamics damping="0.1" friction="10.0"/>
    <limit effort="79.79" lower="-3.0543261909900767" upper="3.0543261909900767" velocity="2.6179938779914944"/>
  </joint>
  <joint name="joint4" type="revolute">
    <parent link="link4"/>
    <child link="link5"/>
    <origin rpy="-1.570796327                         0                         3.14159265" xyz="0                          -0.1305                          0.3628"/>
    <axis xyz="0 0 1"/>
    <dynamics damping="0.1" friction="10.0"/>
    <limit effort="79.79" lower="-3.0543261909900767" upper="3.0543261909900767" velocity="2.6179938779914944"/>
  </joint>
  <joint name="joint5" type="revolute">
    <parent link="link5"/>
    <child link="link6"/>
    <origin rpy="-1.570796327                         0                         3.14159265" xyz="0                          -0.075                          0.08"/>
    <axis xyz="0 0 1"/>
    <dynamics damping="0.1" friction="10.0"/>
    <limit effort="79.79" lower="-3.7524578917878086" upper="3.7524578917878086" velocity="2.6179938779914944"/>
  </joint>
  <joint name="tcp" type="fixed">
    <parent link="link6"/>
    <child link="tcp"/>
    <origin rpy="0.0                         0.0                         0.0" xyz="0.0                          0.0                          0.09"/>
  </joint>
  <transmission name="tran0">
    <type>transmission_interface/SimpleTransmission</type>
    <joint name="joint0">
      <hardwareInterface>hardware_interface/PositionJointInterface</hardwareInterface>
    </joint>
    <actuator name="motor0">
      <mechanicalReduction>1</mechanicalReduction>
    </actuator>
  </transmission>
  <transmission name="tran1">
    <type>transmission_interface/SimpleTransmission</type>
    <joint name="joint1">
      <hardwareInterface>hardware_interface/PositionJointInterface</hardwareInterface>
    </joint>
    <actuator name="motor1">
      <mechanicalReduction>1</mechanicalReduction>
    </actuator>
  </transmission>
  <transmission name="tran2">
    <type>transmission_interface/SimpleTransmission</type>
    <joint name="joint2">
      <hardwareInterface>hardware_interface/PositionJointInterface</hardwareInterface>
    </joint>
    <actuator name="motor2">
      <mechanicalReduction>1</mechanicalReduction>
    </actuator>
  </transmission>
  <transmission name="tran3">
    <type>transmission_interface/SimpleTransmission</type>
    <joint name="joint3">
      <hardwareInterface>hardware_interface/PositionJointInterface</hardwareInterface>
    </joint>
    <actuator name="motor3">
      <mechanicalReduction>1</mechanicalReduction>
    </actuator>
  </transmission>
  <transmission name="tran4">
    <type>transmission_interface/SimpleTransmission</type>
    <joint name="joint4">
      <hardwareInterface>hardware_interface/PositionJointInterface</hardwareInterface>
    </joint>
    <actuator name="motor4">
      <mechanicalReduction>1</mechanicalReduction>
    </actuator>
  </transmission>
  <transmission name="tran5">
    <type>transmission_interface/SimpleTransmission</type>
    <joint name="joint5">
      <hardwareInterface>hardware_interface/PositionJointInterface</hardwareInterface>
    </joint>
    <actuator name="motor5">
      <mechanicalReduction>1</mechanicalReduction>
    </actuator>
  </transmission>
</robot>
