<?xml version="1.0" ?>
<!-- =================================================================================== -->
<!-- |    This document was autogenerated by xacro from indy.urdf.xacro                | -->
<!-- |    EDITING THIS FILE BY HAND IS NOT RECOMMENDED                                 | -->
<!-- =================================================================================== -->
<robot name="indy">
  <material name="black">
    <color rgba="0.0 0.0 0.0 1.0"/>
  </material>
  <material name="blue">
    <color rgba="0.0 0.0 0.8 1.0"/>
  </material>
  <material name="green">
    <color rgba="0.0 0.8 0.0 1.0"/>
  </material>
  <material name="icon_green">
    <color rgba="0.596078431372549 0.7764705882352941 0.3843137254901961 1.0"/>
  </material>
  <material name="icon_grey">
    <color rgba="0.2 0.2 0.2 1.0"/>
  </material>
  <material name="indy_white">
    <color rgba="0.8941176470588236 0.8941176470588236 0.8941176470588236 1.0"/>
  </material>
  <material name="grey">
    <color rgba="0.2 0.2 0.2 1.0"/>
  </material>
  <material name="orange">
    <color rgba="1.0 0.4235294117647059 0.0392156862745098 1.0"/>
  </material>
  <material name="brown">
    <color rgba="0.8705882352941177 0.8117647058823529 0.7647058823529411 1.0"/>
  </material>
  <material name="red">
    <color rgba="0.8 0.0 0.0 1.0"/>
  </material>
  <material name="white">
    <color rgba="1.0 1.0 1.0 1.0"/>
  </material>
  <material name="metal">
    <color rgba="0.768627450980392 0.749019607843137 0.729411764705882 1"/>
  </material>
  <material name="metal_grey">
    <color rgba="0.501960784313725 0.501960784313725 0.501960784313725 1"/>
  </material>
  <material name="metal_white">
    <color rgba="0.866666666666667 0.866666666666667 0.890196078431373 1"/>
  </material>
  <link name="world"/>
  <link name="link0">
    <visual>
      <origin rpy="0 0 0" xyz="0 0 0"/>
      <geometry>
        <mesh filename="file:///home/user/indy-ros/src/indy_description/meshes/nuri7c/visual/Nuri7c_0.stl"/>
      </geometry>
      <material name="indy_white"/>
    </visual>
    <collision>
      <origin rpy="0 0 0" xyz="0 0 0"/>
      <geometry>
        <mesh filename="file:///home/user/indy-ros/src/indy_description/meshes/nuri7c/collision/Nuri7c_0.stl"/>
      </geometry>
    </collision>
    <inertial>
      <mass value="4.23"/>
      <origin rpy="0 0 0" xyz="-0.0008162542                             -0.0018044222                             0.084760414"/>
      <inertia ixx="0.0305782935" ixy="-3.19768e-05" ixz="0.0002359424" iyy="0.0305865023" iyz="0.0004442242" izz="0.0304509048"/>
    </inertial>
  </link>
  <link name="link1">
    <visual>
      <origin rpy="0 0 0" xyz="0 0 0"/>
      <geometry>
        <mesh filename="file:///home/user/indy-ros/src/indy_description/meshes/nuri7c/visual/Nuri7c_1.stl"/>
      </geometry>
      <material name="indy_white"/>
    </visual>
    <collision>
      <origin rpy="0 0 0" xyz="0 0 0"/>
      <geometry>
        <mesh filename="file:///home/user/indy-ros/src/indy_description/meshes/nuri7c/collision/Nuri7c_1.stl"/>
      </geometry>
    </collision>
    <inertial>
      <mass value="5.489055681"/>
      <origin rpy="0 0 0" xyz="-5.783e-06                             0.035425652                             0.173360636"/>
      <inertia ixx="0.49303867" ixy="-0.00010899" ixz="5.122e-05" iyy="0.37221789" iyz="0.13262003" izz="0.28236662"/>
    </inertial>
  </link>
  <link name="link2">
    <visual>
      <origin rpy="0 0 0" xyz="0 0 0"/>
      <geometry>
        <mesh filename="file:///home/user/indy-ros/src/indy_description/meshes/nuri7c/visual/Nuri7c_2.stl"/>
      </geometry>
      <material name="indy_white"/>
    </visual>
    <collision>
      <origin rpy="0 0 0" xyz="0 0 0"/>
      <geometry>
        <mesh filename="file:///home/user/indy-ros/src/indy_description/meshes/nuri7c/collision/Nuri7c_2.stl"/>
      </geometry>
    </collision>
    <inertial>
      <mass value="7.28078719"/>
      <origin rpy="0 0 0" xyz="-5.843e-06                             0.155018004                             0.199572325"/>
      <inertia ixx="3.42183385" ixy="-2.429e-05" ixz="-0.00059164" iyy="3.37349017" iyz="0.07466562" izz="0.25164737"/>
    </inertial>
  </link>
  <link name="link3">
    <visual>
      <origin rpy="0 0 0" xyz="0 0 0"/>
      <geometry>
        <mesh filename="file:///home/user/indy-ros/src/indy_description/meshes/nuri7c/visual/Nuri7c_3.stl"/>
      </geometry>
      <material name="indy_white"/>
    </visual>
    <collision>
      <origin rpy="0 0 0" xyz="0 0 0"/>
      <geometry>
        <mesh filename="file:///home/user/indy-ros/src/indy_description/meshes/nuri7c/collision/Nuri7c_3.stl"/>
      </geometry>
    </collision>
    <inertial>
      <mass value="2.871921442"/>
      <origin rpy="0 0 0" xyz="-1.2233e-05                             -0.044249483                             0.048944532"/>
      <inertia ixx="0.20899594" ixy="-1.925e-05" ixz="2.42e-06" iyy="0.13076166" iyz="0.06293742" izz="0.12136455"/>
    </inertial>
  </link>
  <link name="link4">
    <visual>
      <origin rpy="0 0 0" xyz="0 0 0"/>
      <geometry>
        <mesh filename="file:///home/user/indy-ros/src/indy_description/meshes/nuri7c/visual/Nuri7c_4.stl"/>
      </geometry>
      <material name="indy_white"/>
    </visual>
    <collision>
      <origin rpy="0 0 0" xyz="0 0 0"/>
      <geometry>
        <mesh filename="file:///home/user/indy-ros/src/indy_description/meshes/nuri7c/collision/Nuri7c_4.stl"/>
      </geometry>
    </collision>
    <inertial>
      <mass value="2.822752725"/>
      <origin rpy="0 0 0" xyz="2.4097e-05                             0.018331465                             -0.08651714"/>
      <inertia ixx="0.31668234" ixy="-2.23e-06" ixz="-4.37e-06" iyy="0.30304755" iyz="0.04367878" izz="0.05689264"/>
    </inertial>
  </link>
  <link name="link5">
    <visual>
      <origin rpy="0 0 0" xyz="0 0 0"/>
      <geometry>
        <mesh filename="file:///home/user/indy-ros/src/indy_description/meshes/nuri7c/visual/Nuri7c_5.stl"/>
      </geometry>
      <material name="indy_white"/>
    </visual>
    <collision>
      <origin rpy="0 0 0" xyz="0 0 0"/>
      <geometry>
        <mesh filename="file:///home/user/indy-ros/src/indy_description/meshes/nuri7c/collision/Nuri7c_5.stl"/>
      </geometry>
    </collision>
    <inertial>
      <mass value="2.340109457"/>
      <origin rpy="0 0 0" xyz="-4.2631e-05                             -0.031099492                             0.014132888"/>
      <inertia ixx="0.09533629" ixy="-2.821e-05" ixz="8.24e-05" iyy="0.05815545" iyz="0.00997174" izz="0.06920849"/>
    </inertial>
  </link>
  <link name="link6">
    <visual>
      <origin rpy="0 0 0" xyz="0 0 0"/>
      <geometry>
        <mesh filename="file:///home/user/indy-ros/src/indy_description/meshes/nuri7c/visual/Nuri7c_6.stl"/>
      </geometry>
      <material name="indy_white"/>
    </visual>
    <collision>
      <origin rpy="0 0 0" xyz="0 0 0"/>
      <geometry>
        <mesh filename="file:///home/user/indy-ros/src/indy_description/meshes/nuri7c/collision/Nuri7c_6.stl"/>
      </geometry>
    </collision>
    <inertial>
      <mass value="1.141750934"/>
      <origin rpy="0 0 0" xyz="1.265e-06                             -0.000200776                             -0.049302167"/>
      <inertia ixx="0.02177431" ixy="-1.78e-06" ixz="-1.55e-06" iyy="0.021883" iyz="-5.703e-05" izz="0.0125122"/>
    </inertial>
  </link>
  <link name="tcp"/>
  <!-- joints -->
  <joint name="global" type="fixed">
    <origin rpy="0 0 0" xyz="0 0 0"/>
    <parent link="world"/>
    <!--world-->
    <child link="link0"/>
  </joint>
  <joint name="joint0" type="revolute">
    <parent link="link0"/>
    <child link="link1"/>
    <origin rpy="0.0                         0.0                         0.0" xyz="0.0                          0.0                          0.0705"/>
    <axis xyz="0 0 1"/>
    <limit effort="431.97" lower="-6.283185307179586" upper="6.283185307179586" velocity="3.141592653589793"/>
  </joint>
  <joint name="joint1" type="revolute">
    <parent link="link1"/>
    <child link="link2"/>
    <origin rpy="1.570796327                         0.0                         0.0" xyz="0.0                          -0.0915                          0.171"/>
    <axis xyz="0 0 1"/>
    <limit effort="431.97" lower="-2.705260340591211" upper="2.443460952792061" velocity="3.141592653589793"/>
  </joint>
  <joint name="joint2" type="revolute">
    <parent link="link2"/>
    <child link="link3"/>
    <origin rpy="0.0                         0.0                         0.0" xyz="0.0                          0.49                          0.0"/>
    <axis xyz="0 0 1"/>
    <limit effort="197.23" lower="-3.0543261909900767" upper="2.356194490192345" velocity="3.141592653589793"/>
  </joint>
  <joint name="joint3" type="revolute">
    <parent link="link3"/>
    <child link="link4"/>
    <origin rpy="-1.570796327                         0.0                         0.0" xyz="0.0                          0.1475                          -0.0915"/>
    <axis xyz="0 0 1"/>
    <limit effort="79.79" lower="-6.283185307179586" upper="6.283185307179586" velocity="3.141592653589793"/>
  </joint>
  <joint name="joint4" type="revolute">
    <parent link="link4"/>
    <child link="link5"/>
    <origin rpy="1.570796327                         0.0                         0.0" xyz="0.0                          0.0737                          0.2125"/>
    <axis xyz="0 0 1"/>
    <limit effort="79.79" lower="-6.283185307179586" upper="6.283185307179586" velocity="3.141592653589793"/>
  </joint>
  <joint name="joint5" type="revolute">
    <parent link="link5"/>
    <child link="link6"/>
    <origin rpy="-1.570796327                         0.0                         0.0" xyz="0.0                          0.073                          -0.0763"/>
    <axis xyz="0 0 1"/>
    <limit effort="79.79" lower="-6.283185307179586" upper="6.283185307179586" velocity="3.141592653589793"/>
  </joint>
  <joint name="tcp" type="fixed">
    <parent link="link6"/>
    <child link="tcp"/>
    <!-- <origin xyz="0 0 0.06" rpy="0 0 0"/> -->
    <origin rpy="0.0                         0.0                         0.0" xyz="0.0                          0.0                          0.054"/>
  </joint>
  <transmission name="tran0">
    <type>transmission_interface/SimpleTransmission</type>
    <joint name="joint0">
      <hardwareInterface>hardware_interface/PositionJointInterface</hardwareInterface>
    </joint>
    <actuator name="motor0">
      <mechanicalReduction>1</mechanicalReduction>
    </actuator>
  </transmission>
  <transmission name="tran1">
    <type>transmission_interface/SimpleTransmission</type>
    <joint name="joint1">
      <hardwareInterface>hardware_interface/PositionJointInterface</hardwareInterface>
    </joint>
    <actuator name="motor1">
      <mechanicalReduction>1</mechanicalReduction>
    </actuator>
  </transmission>
  <transmission name="tran2">
    <type>transmission_interface/SimpleTransmission</type>
    <joint name="joint2">
      <hardwareInterface>hardware_interface/PositionJointInterface</hardwareInterface>
    </joint>
    <actuator name="motor2">
      <mechanicalReduction>1</mechanicalReduction>
    </actuator>
  </transmission>
  <transmission name="tran3">
    <type>transmission_interface/SimpleTransmission</type>
    <joint name="joint3">
      <hardwareInterface>hardware_interface/PositionJointInterface</hardwareInterface>
    </joint>
    <actuator name="motor3">
      <mechanicalReduction>1</mechanicalReduction>
    </actuator>
  </transmission>
  <transmission name="tran4">
    <type>transmission_interface/SimpleTransmission</type>
    <joint name="joint4">
      <hardwareInterface>hardware_interface/PositionJointInterface</hardwareInterface>
    </joint>
    <actuator name="motor4">
      <mechanicalReduction>1</mechanicalReduction>
    </actuator>
  </transmission>
  <transmission name="tran5">
    <type>transmission_interface/SimpleTransmission</type>
    <joint name="joint5">
      <hardwareInterface>hardware_interface/PositionJointInterface</hardwareInterface>
    </joint>
    <actuator name="motor5">
      <mechanicalReduction>1</mechanicalReduction>
    </actuator>
  </transmission>
</robot>
