<?xml version="1.0" ?>
<robot name = "indy5" xmlns:xacro="http://ros.org/wiki/xacro">
	<xacro:include filename="$(find indy5_description)/urdf/materials.xacro" />
	<xacro:property name="PI" value="3.1415926535897931"/>
	<xacro:property name="indy_material" value="metal_grey"/>
	
	<link name = "ground" />
    <link name = "link0">
        <visual>
            <origin xyz = "0 0 0" rpy = "0 0 0"/>
           	<geometry>
				<mesh filename="package://indy5_description/meshes/stl/Indy5_0.stl" />
			</geometry>
			<material name="${indy_material}"/>
        </visual>
         <collision>
            <origin xyz="0 0 0" rpy="0 0 0"/>
           	<geometry>
				<mesh filename="package://indy5_description/meshes/stl/Indy5_0.stl" />
			</geometry>
        </collision>        
         <inertial>
            <origin xyz="0 0 0" rpy="0 0 0"/>
            <mass value="1.59306955" />
            <inertia ixx="+0.00572623" iyy="+0.00558959" izz="+0.00966674" ixy="+0.00000251" iyz="-0.00000014" ixz="-0.00011380"/>
        </inertial>
    </link>

	<link name = "link1">
        <visual>
            <origin xyz = "0 0 0" rpy = "0 0 0"/>
           	<geometry>
				<mesh filename="package://indy5_description/meshes/stl/Indy5_1.stl" />
			</geometry>
			<material name="${indy_material}"/>
        </visual>
         <collision>
            <origin xyz="0 0 0" rpy="0 0 0"/>
           	<geometry>
				<mesh filename="package://indy5_description/meshes/stl/Indy5_1.stl" />
			</geometry>
        </collision>    
         <inertial>
            <origin xyz="0 0 0" rpy="0 0 0"/>
            <mass value="1.59306955" />
            <inertia ixx="+0.15418559" iyy="+0.12937017" izz="+0.05964415" ixy="-0.00000235" iyz="-0.04854267" ixz="+0.00001739" />
        </inertial>
    </link>

    <link name = "link2">
        <visual>
            <origin xyz = "0 0 0" rpy = "0 0 0"/>
           	<geometry>
				<mesh filename="package://indy5_description/meshes/stl/Indy5_2.stl" />
			</geometry>
			<material name="${indy_material}"/>
        </visual>
         <collision>
            <origin xyz="0 0 0" rpy="0 0 0"/>
           	<geometry>
				<mesh filename="package://indy5_description/meshes/stl/Indy5_2.stl" />
			</geometry>
        </collision>
         <inertial>
            <origin xyz="0 0 0" rpy="0 0 0"/>
            <mass value="0.18" />
            <inertia ixx="+0.29356980" iyy="+0.25088420" izz="+0.03620519" ixy="-0.00000040" iyz="+0.03727972" ixz="+0.00001441"/>
        </inertial>
    </link>

    <link name = "link3">
    	<visual>
            <origin xyz = "0 0 0" rpy = "0 0 0"/>
           	<geometry>
				<mesh filename="package://indy5_description/meshes/stl/Indy5_3.stl" />
			</geometry>
			<material name="${indy_material}"/>
        </visual>
         <collision>
            <origin xyz="0 0 0" rpy="0 0 0"/>
           	<geometry>
				<mesh filename="package://indy5_description/meshes/stl/Indy5_3.stl" />
			</geometry>
        </collision>
         <inertial>
            <origin xyz="0 0 0" rpy="0 0 0"/>
            <mass value="0.18" />
            <inertia ixx="+0.03424593" iyy="+0.03406024" izz="+0.00450477" ixy="+0.00000149" iyz="+0.00186009" ixz="+0.00000724"/>
        </inertial>
    </link>
 
    <link name = "link4">
    	<visual>
            <origin xyz = "0 0 0" rpy = "0 0 0"/>
           	<geometry>
				<mesh filename="package://indy5_description/meshes/stl/Indy5_4.stl" />
			</geometry>
			<material name="${indy_material}"/>
        </visual>
         <collision>
            <origin xyz="0 0 0" rpy="0 0 0"/>
           	<geometry>
				<mesh filename="package://indy5_description/meshes/stl/Indy5_4.stl" />
			</geometry>
        </collision>
         <inertial>
            <origin xyz="0 0 0" rpy="0 0 0"/>
            <mass value="0.18" />
            <inertia ixx="+0.00670405" iyy="+0.00670405" izz="+0.00617624" ixy="+0.00000375" iyz="-0.00127967" ixz="+0.00000150"/>
        </inertial>
    </link>

    <link name = "link5">
    	<visual>
            <origin xyz = "0 0 0" rpy = "0 0 0"/>
           	<geometry>
				<mesh filename="package://indy5_description/meshes/stl/Indy5_5.stl" />
			</geometry>
			<material name="${indy_material}"/>
        </visual>
         <collision>
            <origin xyz="0 0 0" rpy="0 0 0"/>
           	<geometry>
				<mesh filename="package://indy5_description/meshes/stl/Indy5_5.stl" />
			</geometry>
        </collision>
         <inertial>
            <origin xyz="0 0 0" rpy="0 0 0"/>
            <mass value="0.18" />
            <inertia ixx="+0.00994891" iyy="+0.00978189" izz="+0.00271492" ixy="+0.00000014" iyz="-0.00093546" ixz="+0.00000321"/>
        </inertial>
    </link>

    <link name = "link6">
    	<visual>
            <origin xyz = "0 0 0" rpy = "0 0 0"/>
           	<geometry>
				<mesh filename="package://indy5_description/meshes/stl/Indy5_6.stl" />
			</geometry>
			<material name="${indy_material}"/>
        </visual>
         <collision>
            <origin xyz="0 0 0" rpy="0 0 0"/>
           	<geometry>
				<mesh filename="package://indy5_description/meshes/stl/Indy5_6.stl" />
			</geometry>
        </collision>
         <inertial>
            <origin xyz="0 0 0" rpy="0 0 0"/>
            <mass value="0.18" />
            <inertia ixx="0.00043534" iyy="0.00044549" izz="0.00059634" ixy="+0.00000013" iyz="+0.00000051" ixz="-0.00000002"/>
        </inertial>
    </link>
    <link name = "tcp" />

    <joint name = "global" type = "fixed">
    	<parent link = "ground"/>
    	<child link = "link0"/>
    	<origin xyz = "0 0 0" rpy = "0 0 0"/>
    </joint>
	
	<joint name = "joint0" type = "continuous">
    	<parent link = "link0"/>
    	<child link = "link1"/>
    	<origin xyz = "0.0 0.00000006 0.074" rpy = "0 0 0"/>
    	<axis xyz = "0 0 1"/>
    </joint>

    <joint name = "joint1" type = "continuous">
    	<parent link = "link1"/>
    	<child link = "link2"/>
    	<origin xyz = "0 0.08500000 0.14600000" rpy = "-${PI/2} -${PI/2} 0"/>
    	<axis xyz = "0 0 1"/>
    </joint>

    <joint name = "joint2" type = "continuous">
    	<parent link = "link2"/>
    	<child link = "link3"/>
    	<origin xyz = "0.38000000 0.00000000 -0.00700000" rpy = "0 0 0"/>
    	<axis xyz = "0 0 1"/>
    </joint>

    <joint name = "joint3" type = "continuous">
    	<parent link = "link3"/>
    	<child link = "link4"/>
    	<origin xyz = "0.12300000 0.00000000 -0.07800000" rpy = "${PI/2} 0 ${PI/2}"/>
    	<axis xyz = "0 0 1"/>
    </joint>

    <joint name = "joint4" type = "continuous">
    	<parent link = "link4"/>
    	<child link = "link5"/>
    	<origin xyz = "0.00000000 0.06500000 0.29700000" rpy = "-${PI/2} -${PI/2} 0"/>
    	<axis xyz = "0 0 1"/>
    </joint>

    <joint name = "joint5" type = "continuous">
    	<parent link = "link5"/>
    	<child link = "link6"/>
    	<origin xyz = "0.10700000 0.00000000 -0.06500000" rpy = "${PI/2} 0 ${PI/2}"/>
    	<axis xyz = "0 0 1"/>
    </joint>

    <joint name = "tcp" type = "fixed">
    	<parent link = "link6"/>
    	<child link = "tcp"/>
    	<origin xyz = "0 0 0.048" rpy = "0 0 0"/>
    </joint>
</robot>