<?xml version="1.0" ?>
<robot name = "indyrp2" xmlns:xacro="http://ros.org/wiki/xacro">
	<xacro:include filename="$(find indyrp2_description)/urdf/materials.xacro" />
	<xacro:property name="PI" value="3.1415926535897931"/>
	<xacro:property name="indy_material" value="metal_grey"/>

	<link name = "world" />
    <link name = "link0">
        <visual>
            <origin xyz = "0 0 0" rpy = "0 0 0"/>
           	<geometry>
				<mesh filename="package://indyrp2_description/meshes/stl/IndyRP2_0.stl" />
			</geometry>
			<material name="${indy_material}"/>
        </visual>
         <collision>
            <origin xyz="0 0 0" rpy="0 0 0"/>
           	<geometry>
				<mesh filename="package://indyrp2_description/meshes/stl/IndyRP2_0.stl" />
			</geometry>
        </collision>        
         <inertial>
            <origin xyz="0 0 0" rpy="0 0 0"/>
            <mass value="5.44309" />
            <inertia ixx="0.0236" iyy="0.0234" izz="0.0137" ixy="0" iyz="0.0001" ixz="0"/>
        </inertial>
    </link>

     <link name = "link1">
        <visual>
            <origin xyz = "0 0 0" rpy = "0 0 0"/>
           	<geometry>
				<mesh filename="package://indyrp2_description/meshes/stl/IndyRP2_1.stl" />
			</geometry>
			<material name="${indy_material}"/>
        </visual>
         <collision>
            <origin xyz="0 0 0" rpy="0 0 0"/>
           	<geometry>
				<mesh filename="package://indyrp2_description/meshes/stl/IndyRP2_1.stl" />
			</geometry>
        </collision>    
         <inertial>
            <origin xyz="0 0 0" rpy="0 0 0"/>
            <mass value="5.50328" />
            <inertia ixx="0.0227" iyy="0.0121" izz="0.0212" ixy="0" iyz="0.0013" ixz="0" />
        </inertial>
    </link>

    <link name = "link2">
        <visual>
            <origin xyz = "0 0 0" rpy = "0 0 0"/>
           	<geometry>
				<mesh filename="package://indyrp2_description/meshes/stl/IndyRP2_2.stl" />
			</geometry>
			<material name="${indy_material}"/>
        </visual>
         <collision>
            <origin xyz="0 0 0" rpy="0 0 0"/>
           	<geometry>
				<mesh filename="package://indyrp2_description/meshes/stl/IndyRP2_2.stl" />
			</geometry>
        </collision>
         <inertial>
            <origin xyz="0 0 0" rpy="0 0 0"/>
            <mass value="5.95397" />
            <inertia ixx="0.1175" iyy="0.1172" izz="0.0131" ixy="00" iyz="0.0037" ixz="0"/>
        </inertial>
    </link>

    <link name = "link3">
    	<visual>
            <origin xyz = "0 0 0" rpy = "0 0 0"/>
           	<geometry>
				<mesh filename="package://indyrp2_description/meshes/stl/IndyRP2_3.stl" />
			</geometry>
			<material name="${indy_material}"/>
        </visual>
         <collision>
            <origin xyz="0 0 0" rpy="0 0 0"/>
           	<geometry>
				<mesh filename="package://indyrp2_description/meshes/stl/IndyRP2_3.stl" />
			</geometry>
        </collision>
         <inertial>
            <origin xyz="0 0 0" rpy="0 0 0"/>
            <mass value="4.08259" />
            <inertia ixx="0.0132" iyy="0.0068" izz="0.0125" ixy="0" iyz="-0.0008" ixz="0"/>
        </inertial>
    </link>

    <link name = "link4">
    	<visual>
            <origin xyz = "0 0 0" rpy = "0 0 0"/>
           	<geometry>
				<mesh filename="package://indyrp2_description/meshes/stl/IndyRP2_4.stl" />
			</geometry>
			<material name="${indy_material}"/>
        </visual>
         <collision>
            <origin xyz="0 0 0" rpy="0 0 0"/>
           	<geometry>
				<mesh filename="package://indyrp2_description/meshes/stl/IndyRP2_4.stl" />
			</geometry>
        </collision>
         <inertial>
            <origin xyz="0 0 0" rpy="0 0 0"/>
            <mass value="4.02733" />
            <inertia ixx="0.0674" iyy="0.067" izz="0.0071" ixy="0" iyz="-0.0027" ixz="0"/>
        </inertial>
    </link>

    <link name = "link5">
    	<visual>
            <origin xyz = "0 0 0" rpy = "0 0 0"/>
           	<geometry>
				<mesh filename="package://indyrp2_description/meshes/stl/IndyRP2_5.stl" />
			</geometry>
			<material name="${indy_material}"/>
        </visual>
         <collision>
            <origin xyz="0 0 0" rpy="0 0 0"/>
           	<geometry>
				<mesh filename="package://indyrp2_description/meshes/stl/IndyRP2_5.stl" />
			</geometry>
        </collision>
         <inertial>
            <origin xyz="0 0 0" rpy="0 0 0"/>
            <mass value="2.52863" />
            <inertia ixx="0.0066" iyy="0.0033" izz="0.0062" ixy="0" iyz="0.0003" ixz="0"/>
        </inertial>
    </link>

    <link name = "link6">
    	<visual>
            <origin xyz = "0 0 0" rpy = "0 0 0"/>
           	<geometry>
				<mesh filename="package://indyrp2_description/meshes/stl/IndyRP2_6.stl" />
			</geometry>
			<material name="${indy_material}"/>
        </visual>
         <collision>
            <origin xyz="0 0 0" rpy="0 0 0"/>
           	<geometry>
				<mesh filename="package://indyrp2_description/meshes/stl/IndyRP2_6.stl" />
			</geometry>
        </collision>
         <inertial>
            <origin xyz="0 0 0" rpy="0 0 0"/>
            <mass value="2.03152" />
            <inertia ixx="0.0042" iyy="0.0041" izz="0.0018" ixy="0" iyz="0.0003" ixz="0"/>
        </inertial>
    </link>

    <link name = "link7">
        <visual>
            <origin xyz = "0 0 0" rpy = "0 0 0"/>
            <geometry>
                <mesh filename="package://indyrp2_description/meshes/stl/IndyRP2_7.stl" />
            </geometry>
            <material name="${indy_material}"/>
        </visual>
         <collision>
            <origin xyz="0 0 0" rpy="0 0 0"/>
            <geometry>
                <mesh filename="package://indyrp2_description/meshes/stl/IndyRP2_7.stl" />
            </geometry>
        </collision>
         <inertial>
            <origin xyz="0 0 0" rpy="0 0 0"/>
            <mass value="0.17194" />
            <inertia ixx="0.0001" iyy="0.0001" izz="0.0001" ixy="0" iyz="0" ixz="0"/>
        </inertial>
    </link>
    <link name = "tcp" />

    <joint name = "global" type = "fixed">
    	<parent link = "world"/>
    	<child link = "link0"/>
    	<origin xyz = "0 0 0" rpy = "0 0 0"/>
    </joint>

    <joint name = "joint0" type = "continuous">
    	<parent link = "link0"/>
    	<child link = "link1"/>
    	<origin xyz = "+0.00000000 +0.00000000 +0.07720000" rpy = "0 0 0"/>
    	<axis xyz = "0 0 1"/>
    </joint>

    <joint name = "joint1" type = "continuous">
    	<parent link = "link1"/>
    	<child link = "link2"/>
    	<origin xyz = "+0.00000000 -0.10930000 +0.22280000" rpy = "${PI/2} ${PI/2} 0"/>
    	<axis xyz = "0 0 1"/>
    </joint>

    <joint name = "joint2" type = "continuous">
    	<parent link = "link2"/>
    	<child link = "link3"/>
    	<origin xyz = "-0.38400000 +0.00000000 +0.08470000" rpy = "-${PI/2} 0 ${PI/2}"/>
    	<axis xyz = "0 0 1"/>
    </joint>

    <joint name = "joint3" type = "continuous">
    	<parent link = "link3"/>
    	<child link = "link4"/>
    	<origin xyz = "+0.00000000 +0.11530000 +0.06550000" rpy = "${PI/2} ${PI/2} 0"/>
    	<axis xyz = "0 0 1"/>
    </joint>

    <joint name = "joint4" type = "continuous">
    	<parent link = "link4"/>
    	<child link = "link5"/>
    	<origin xyz = "-0.26650000 +0.00000000 -0.07470000" rpy = "-${PI/2} 0 ${PI/2}"/>
    	<axis xyz = "0 0 1"/>
    </joint>

    <joint name = "joint5" type = "continuous">
    	<parent link = "link5"/>
    	<child link = "link6"/>
    	<origin xyz = "+0.00000000 -0.11430000 +0.08350000" rpy = "${PI/2} ${PI/2} 0"/>
    	<axis xyz = "0 0 1"/>
    </joint>

    <joint name = "joint6" type = "continuous">
        <parent link = "link6"/>
        <child link = "link7"/>
        <origin xyz = "-0.16800000 +0.00000000 +0.06870000" rpy = "-${PI/2} 0 ${PI/2}"/>
        <axis xyz = "0 0 1"/>
    </joint>

    <joint name = "tcp" type = "fixed">
    	<parent link = "link7"/>
    	<child link = "tcp"/>
    	<origin xyz = "0 0 0.06" rpy = "0 0 0"/>
    </joint>


</robot>