<?xml version="1.0" ?>
<robot name = "indyrp2" xmlns:xacro="http://ros.org/wiki/xacro">
	<xacro:include filename="$(find indyrp2_description)/urdf/materials.xacro" />
	<xacro:include filename="$(find indyrp2_description)/urdf/indyrp2.gazebo"/>
	<xacro:property name="PI" value="3.1415926535897931"/>
	<xacro:property name="indy_material" value="metal_grey"/>

	<link name = "world" />
    <link name = "link0">
        <visual>
            <origin xyz = "0 0 0" rpy = "0 0 0"/>
           	<geometry>
				<mesh filename="package://indyrp2_description/meshes/stl/IndyRP2_0.stl" />
			</geometry>
			<material name="${indy_material}"/>
        </visual>
         <collision>
            <origin xyz="0 0 0" rpy="0 0 0"/>
           	<geometry>
				<mesh filename="package://indyrp2_description/meshes/stl/IndyRP2_0.stl" />
			</geometry>
        </collision>        
         <inertial>
            <origin xyz="0.00131966 -0.00000218 0.03212832" rpy="0 0 0"/>
			<mass value="1.67030785"/>
			<inertia ixx="+0.00661309" iyy="+0.00644765" izz="+0.00792090" ixy="+0.00000183" iyz="-0.00000027" ixz="+0.00002695"/>
        </inertial>
    </link>

     <link name = "link1">
        <visual>
            <origin xyz = "0 0 0" rpy = "0 0 0"/>
           	<geometry>
				<mesh filename="package://indyrp2_description/meshes/stl/IndyRP2_1.stl" />
			</geometry>
			<material name="${indy_material}"/>
        </visual>
         <collision>
            <origin xyz="0 0 0" rpy="0 0 0"/>
           	<geometry>
				<mesh filename="package://indyrp2_description/meshes/stl/IndyRP2_1.stl" />
			</geometry>
        </collision>    
         <inertial>
            <origin xyz="-0.00023749 -0.04310313 0.13245396" rpy="0 0 0"/>
			<mass value="11.44444535"/>
			<inertia ixx="+0.35065005" iyy="+0.30479800" izz="+0.06003147" ixy="+0.00011931" iyz="-0.10984447" ixz="-0.00037553"/>
        </inertial>
    </link>

    <link name = "link2">
        <visual>
            <origin xyz = "0 0 0" rpy = "0 0 0"/>
           	<geometry>
				<mesh filename="package://indyrp2_description/meshes/stl/IndyRP2_2.stl" />
			</geometry>
			<material name="${indy_material}"/>
        </visual>
         <collision>
            <origin xyz="0 0 0" rpy="0 0 0"/>
           	<geometry>
				<mesh filename="package://indyrp2_description/meshes/stl/IndyRP2_2.stl" />
			</geometry>
        </collision>
         <inertial>
            <origin xyz="-0.21209188 -0.00001715 0.07901191" rpy="0 0 0"/>
            <mass value="4.43308185" />
            <inertia ixx="+0.03742681" iyy="+0.32119654" izz="+0.29396155" ixy="+0.00003176" iyz="-0.00000808" ixz="-0.07906734"/>
        </inertial>
    </link>

    <link name = "link3">
    	<visual>
            <origin xyz = "0 0 0" rpy = "0 0 0"/>
           	<geometry>
				<mesh filename="package://indyrp2_description/meshes/stl/IndyRP2_3.stl" />
			</geometry>
			<material name="${indy_material}"/>
        </visual>
         <collision>
            <origin xyz="0 0 0" rpy="0 0 0"/>
           	<geometry>
				<mesh filename="package://indyrp2_description/meshes/stl/IndyRP2_3.stl" />
			</geometry>
        </collision>
         <inertial>
            <origin xyz="0.00003637 0.07143055 0.07746050" rpy="0 0 0"/>
            <mass value="2.87045928" />
            <inertia ixx="+0.04098160" iyy="+0.02106773" izz="+0.02277477" ixy="+0.00000747" iyz="+0.01817157" ixz="+0.00000916"/>
        </inertial>
    </link>

    <link name = "link4">
    	<visual>
            <origin xyz = "0 0 0" rpy = "0 0 0"/>
           	<geometry>
				<mesh filename="package://indyrp2_description/meshes/stl/IndyRP2_4.stl" />
			</geometry>
			<material name="${indy_material}"/>
        </visual>
         <collision>
            <origin xyz="0 0 0" rpy="0 0 0"/>
           	<geometry>
				<mesh filename="package://indyrp2_description/meshes/stl/IndyRP2_4.stl" />
			</geometry>
        </collision>
         <inertial>
            <origin xyz="-0.16804016 0.00021421 -0.07000383" rpy="0 0 0"/>
			<mass value="2.68206064"/>
			<inertia ixx="+0.01617210" iyy="+0.11364055" izz="+0.10022522" ixy="-0.00011817" iyz="-0.00004371" ixz="+0.03341882"/>
        </inertial>
    </link>

    <link name = "link5">
    	<visual>
            <origin xyz = "0 0 0" rpy = "0 0 0"/>
           	<geometry>
				<mesh filename="package://indyrp2_description/meshes/stl/IndyRP2_5.stl" />
			</geometry>
			<material name="${indy_material}"/>
        </visual>
         <collision>
            <origin xyz="0 0 0" rpy="0 0 0"/>
           	<geometry>
				<mesh filename="package://indyrp2_description/meshes/stl/IndyRP2_5.stl" />
			</geometry>
        </collision>
         <inertial>
            <origin xyz="-0.00026847 -0.07098440 0.07649128" rpy="0 0 0"/>
			<mass value="2.12987371"/>
			<inertia ixx="+0.02798891" iyy="+0.01443076" izz="+0.01496211" ixy="+0.00003893" iyz="-0.01266296" ixz="-0.00004768"/>
        </inertial>
    </link>

    <link name = "link6">
    	<visual>
            <origin xyz = "0 0 0" rpy = "0 0 0"/>
           	<geometry>
				<mesh filename="package://indyrp2_description/meshes/stl/IndyRP2_6.stl" />
			</geometry>
			<material name="${indy_material}"/>
        </visual>
         <collision>
            <origin xyz="0 0 0" rpy="0 0 0"/>
           	<geometry>
				<mesh filename="package://indyrp2_description/meshes/stl/IndyRP2_6.stl" />
			</geometry>
        </collision>
         <inertial>
            <origin xyz="-0.09796232 -0.00023114 0.06445892" rpy="0 0 0"/>
			<mass value="2.22412271"/>
			<inertia ixx="+0.01105297" iyy="+0.03698291" izz="+0.02754795" ixy="+0.00005517" iyz="-0.00003740" ixz="-0.01481977"/>
        </inertial>
    </link>

    <link name = "link7">
        <visual>
            <origin xyz = "0 0 0" rpy = "0 0 0"/>
            <geometry>
                <mesh filename="package://indyrp2_description/meshes/stl/IndyRP2_7.stl" />
            </geometry>
            <material name="${indy_material}"/>
        </visual>
         <collision>
            <origin xyz="0 0 0" rpy="0 0 0"/>
            <geometry>
                <mesh filename="package://indyrp2_description/meshes/stl/IndyRP2_7.stl" />
            </geometry>
        </collision>
         <inertial>
            <origin xyz="0.00008147 -0.00046556 0.03079097" rpy="0 0 0"/>
			<mass value="0.38254932"/>
			<inertia ixx="+0.00078982" iyy="+0.00079764" izz="+0.00058319" ixy="-0.00000034" iyz="-0.00000508" ixz="+0.00000083"/>
        </inertial>
    </link>
    <link name = "tcp" />

    <joint name = "global" type = "fixed">
    	<parent link = "world"/>
    	<child link = "link0"/>
    	<origin xyz = "0 0 0" rpy = "0 0 0"/>
    </joint>

    <joint name = "joint0" type = "revolute">
    	<parent link = "link0"/>
    	<child link = "link1"/>
    	<origin xyz = "+0.00000000 +0.00000000 +0.07720000" rpy = "0 0 0"/>
    	<axis xyz = "0 0 1"/>
		<limit effort="10" velocity="1" lower="-${175*PI/180}" upper="${175*PI/180}"/>
    </joint>

    <joint name = "joint1" type = "revolute">
    	<parent link = "link1"/>
    	<child link = "link2"/>
    	<origin xyz = "+0.00000000 -0.10930000 +0.22280000" rpy = "${PI/2} ${PI/2} 0"/>
    	<axis xyz = "0 0 1"/>
		<limit effort="10" velocity="1" lower="-${175*PI/180}" upper="${175*PI/180}"/>
    </joint>

    <joint name = "joint2" type = "revolute">
    	<parent link = "link2"/>
    	<child link = "link3"/>
    	<origin xyz = "-0.38400000 +0.00000000 +0.08470000" rpy = "-${PI/2} 0 ${PI/2}"/>
    	<axis xyz = "0 0 1"/>
		<limit effort="10" velocity="1" lower="-${175*PI/180}" upper="${175*PI/180}"/>
    </joint>

    <joint name = "joint3" type = "revolute">
    	<parent link = "link3"/>
    	<child link = "link4"/>
    	<origin xyz = "+0.00000000 +0.11530000 +0.06550000" rpy = "${PI/2} ${PI/2} 0"/>
    	<axis xyz = "0 0 1"/>
		<limit effort="10" velocity="1" lower="-${175*PI/180}" upper="${175*PI/180}"/>
    </joint>

    <joint name = "joint4" type = "revolute">
    	<parent link = "link4"/>
    	<child link = "link5"/>
    	<origin xyz = "-0.26650000 +0.00000000 -0.07470000" rpy = "-${PI/2} 0 ${PI/2}"/>
    	<axis xyz = "0 0 1"/>
		<limit effort="10" velocity="1" lower="-${175*PI/180}" upper="${175*PI/180}"/>
    </joint>

    <joint name = "joint5" type = "revolute">
    	<parent link = "link5"/>
    	<child link = "link6"/>
    	<origin xyz = "+0.00000000 -0.11430000 +0.08350000" rpy = "${PI/2} ${PI/2} 0"/>
    	<axis xyz = "0 0 1"/>
		<limit effort="10" velocity="1" lower="-${175*PI/180}" upper="${175*PI/180}"/>
    </joint>

    <joint name = "joint6" type = "revolute">
        <parent link = "link6"/>
        <child link = "link7"/>
        <origin xyz = "-0.16800000 +0.00000000 +0.06870000" rpy = "-${PI/2} 0 ${PI/2}"/>
        <axis xyz = "0 0 1"/>
		<limit effort="10" velocity="1" lower="-${175*PI/180}" upper="${175*PI/180}"/>
    </joint>

    <joint name = "tcp" type = "fixed">
    	<parent link = "link7"/>
    	<child link = "tcp"/>
    	<origin xyz = "0 0 0.06" rpy = "0 0 0"/>
    </joint>

	<transmission name="tran0">
		<type>transmission_interface/SimpleTransmission</type>
		<joint name="joint0">
			<hardwareInterface>hardware_interface/PositionJointInterface</hardwareInterface>
		</joint>
		<actuator name="motor0">
			<hardwareInterface>hardware_interface/PositionJointInterface</hardwareInterface>
			<mechanicalReduction>1</mechanicalReduction>
		</actuator>
	</transmission>

	<transmission name="tran1">
		<type>transmission_interface/SimpleTransmission</type>
		<joint name="joint1">
			<hardwareInterface>hardware_interface/PositionJointInterface</hardwareInterface>
		</joint>
		<actuator name="motor1">
			<hardwareInterface>hardware_interface/PositionJointInterface</hardwareInterface>
			<mechanicalReduction>1</mechanicalReduction>
		</actuator>
	</transmission>

	<transmission name="tran2">
		<type>transmission_interface/SimpleTransmission</type>
		<joint name="joint2">
			<hardwareInterface>hardware_interface/PositionJointInterface</hardwareInterface>
		</joint>
		<actuator name="motor2">
			<hardwareInterface>hardware_interface/PositionJointInterface</hardwareInterface>
			<mechanicalReduction>1</mechanicalReduction>
		</actuator>
	</transmission>

	<transmission name="tran3">
		<type>transmission_interface/SimpleTransmission</type>
		<joint name="joint3">
			<hardwareInterface>hardware_interface/PositionJointInterface</hardwareInterface>
		</joint>
		<actuator name="motor3">
			<hardwareInterface>hardware_interface/PositionJointInterface</hardwareInterface>
			<mechanicalReduction>1</mechanicalReduction>
		</actuator>
	</transmission>

	<transmission name="tran4">
		<type>transmission_interface/SimpleTransmission</type>
		<joint name="joint4">
			<hardwareInterface>hardware_interface/PositionJointInterface</hardwareInterface>
		</joint>
		<actuator name="motor4">
			<hardwareInterface>hardware_interface/PositionJointInterface</hardwareInterface>
			<mechanicalReduction>1</mechanicalReduction>
		</actuator>
	</transmission>

	<transmission name="tran5">
		<type>transmission_interface/SimpleTransmission</type>
		<joint name="joint5">
			<hardwareInterface>hardware_interface/PositionJointInterface</hardwareInterface>
		</joint>
		<actuator name="motor5">
			<hardwareInterface>hardware_interface/PositionJointInterface</hardwareInterface>
			<mechanicalReduction>1</mechanicalReduction>
		</actuator>
	</transmission>

	<transmission name="tran6">
		<type>transmission_interface/SimpleTransmission</type>
		<joint name="joint6">
			<hardwareInterface>hardware_interface/PositionJointInterface</hardwareInterface>
		</joint>
		<actuator name="motor6">
			<hardwareInterface>hardware_interface/PositionJointInterface</hardwareInterface>
			<mechanicalReduction>1</mechanicalReduction>
		</actuator>
	</transmission>

</robot>