<?xml version="1.0" ?>
<robot name="indy7" xmlns:xacro="http://ros.org/wiki/xacro">
	<xacro:include filename="$(find indy7_description)/urdf/materials.xacro"/>
	<xacro:include filename="$(find indy7_description)/urdf/indy7.gazebo"/>

	<xacro:property name="PI" value="3.1415926535897931"/>
	<xacro:property name="indy_material" value="metal_grey"/>
	<!-- <material name="grey"> <color rgba="0.5 0.5 0.5 1"/> </material> -->

	<link name="link0">
		<visual>
			<origin xyz="0 0 0" rpy="0 0 0"/>
			<geometry>
				<mesh filename="package://indy7_description/meshes/stl/Indy7_0.stl"/>
			</geometry>
			<material name="${indy_material}"/>
		</visual>
		<collision>
			<origin xyz="0 0 0" rpy="0 0 0"/>
			<geometry>
				<cylinder length="0.075" radius="0.102"/>
			</geometry>
		</collision>
		<inertial>
			<origin xyz="0 0 0" rpy="0 0 0"/>
			<mass value="1.59306955"/>
			<inertia ixx="+0.00572623" iyy="+0.00558959" izz="+0.00966674" ixy="+0.00000251" iyz="-0.00000014" ixz="-0.00011380"/>
		</inertial>
	</link>

	<link name="link1">
		<visual>
			<origin xyz="0 0 0" rpy="0 0 0"/>
			<geometry>
				<mesh filename="package://indy7_description/meshes/stl/Indy7_1.stl"/>
			</geometry>
			<material name="${indy_material}"/>
		</visual>
		<collision>
			<origin xyz="0 0 0.111" rpy="0 0 0"/>
			<geometry>
				<cylinder length="0.222" radius="0.075"/>
			</geometry>
		</collision>
		<collision>
			<origin xyz="0 -0.0545 0.222" rpy="${PI/2} 0 0"/>
			<geometry>
				<cylinder length="0.109" radius="0.075"/>
			</geometry>
		</collision>
		<inertial>
			<origin xyz="0 0 0" rpy="0 0 0"/>
			<mass value="11.8030102"/>
			<inertia ixx="+0.15418559" iyy="+0.12937017" izz="+0.05964415" ixy="-0.00000235" iyz="-0.04854267" ixz="+0.00001739"/>
		</inertial>
	</link>

	<link name="link2">
		<visual>
			<origin xyz="0 0 0" rpy="0 0 0"/>
			<geometry>
				<mesh filename="package://indy7_description/meshes/stl/Indy7_2.stl"/>
			</geometry>
			<material name="${indy_material}"/>
		</visual>
		<collision>
			<origin xyz="-0.225 0 0.09" rpy="${PI/2} 0 -${PI/2}"/>
			<geometry>
				<cylinder length="0.450" radius="0.063"/>
			</geometry>
		</collision>
		<collision>
			<origin xyz="0 0 0.045" rpy="0 0 0"/>
			<geometry>
				<cylinder length="0.09" radius="0.075"/>
			</geometry>
		</collision>
		<collision>
			<origin xyz="-0.45 0 0.02975 " rpy="0 0 0"/>
			<geometry>
				<cylinder length="0.1205" radius="0.045"/>
			</geometry>
		</collision>
		<inertial>
			<origin xyz="0 0 0" rpy="0 0 0"/>
			<mass value="7.99292141"/>
			<inertia ixx="+0.29356980" iyy="+0.28094142" izz="+0.03620609" ixy="-0.00000040" iyz="+0.03727972" ixz="+0.00001441"/>
		</inertial>
	</link>

	<link name="link3">
		<visual>
			<origin xyz="0 0 0" rpy="0 0 0"/>
			<geometry>
				<mesh filename="package://indy7_description/meshes/stl/Indy7_3.stl"/>
			</geometry>
			<material name="${indy_material}"/>
		</visual>
		<collision>
			<origin xyz="-0.1335 0 -0.075" rpy="${PI/2} 0 -${PI/2}"/>
			<geometry>
				<cylinder length="0.267" radius="0.045"/>
			</geometry>
		</collision>
		<collision>
			<origin xyz="0 0 -0.0375" rpy="0 0 0"/>
			<geometry>
				<cylinder length="0.075" radius="0.045"/>
			</geometry>
		</collision>
		<inertial>
			<origin xyz="0 0 0" rpy="0 0 0"/>
			<mass value="2.99134127"/>
			<inertia ixx="+0.03424593" iyy="+0.03406024" izz="+0.00450477" ixy="+0.00000149" iyz="+0.00186009" ixz="+0.00000724"/>
		</inertial>
	</link>

	<link name="link4">
		<visual>
			<origin xyz="0 0 0" rpy="0 0 0"/>
			<geometry>
				<mesh filename="package://indy7_description/meshes/stl/Indy7_4.stl"/>
			</geometry>
			<material name="${indy_material}"/>
		</visual>
		<collision>
			<origin xyz="0 -0.057 0.083" rpy="${PI/2} 0 0"/>
			<geometry>
				<cylinder length="0.114" radius="0.045"/>
			</geometry>
		</collision>
		<collision>
			<origin xyz="0 -0.057 0.083" rpy="${PI/2} 0 0"/>
			<geometry>
				<cylinder length="0.114" radius="0.045"/>
			</geometry>
		</collision>
		<collision>
			<origin xyz="0 0 0.0415" rpy="0 0 0"/>
			<geometry>
				<cylinder length="0.083" radius="0.045"/>
			</geometry>
		</collision>
		<inertial>
			<origin xyz="0 0 0" rpy="0 0 0"/>
			<mass value="2.12317035"/>
			<inertia ixx="+0.00670405" iyy="+0.00279246" izz="+0.00619341" ixy="+0.00000375" iyz="-0.00127967" ixz="+0.00000150"/>
		</inertial>
	</link>

	<link name="link5">
		<visual>
			<origin xyz="0 0 0" rpy="0 0 0"/>
			<geometry>
				<mesh filename="package://indy7_description/meshes/stl/Indy7_5.stl"/>
			</geometry>
			<material name="${indy_material}"/>
		</visual>
		<collision>
			<origin xyz="-0.084 0 0.069" rpy="${PI/2} 0 -${PI/2}"/>
			<geometry>
				<cylinder length="0.168" radius="0.045"/>
			</geometry>
		</collision>
		<collision>
			<origin xyz="-0 0 0.0345" rpy="0 0 0"/>
			<geometry>
				<cylinder length="0.069" radius="0.045"/>
			</geometry>
		</collision>
		<inertial>
			<origin xyz="0 0 0" rpy="0 0 0"/>
			<mass value="2.28865091"/>
			<inertia ixx="+0.00994891" iyy="+0.00978189" izz="+0.00271492" ixy="+0.00000014" iyz="-0.00093546" ixz="+0.00000321"/>
		</inertial>
	</link>

	<link name="link6">
		<visual>
			<origin xyz="0 0 0" rpy="0 0 0"/>
			<geometry>
				<mesh filename="package://indy7_description/meshes/stl/Indy7_6.stl"/>
			</geometry>
			<material name="${indy_material}"/>
		</visual>
		<collision>
			<origin xyz="0 0 0.03" rpy="0 0 0"/>
			<geometry>
				<cylinder length="0.06" radius="0.045"/>
			</geometry>
		</collision>
		<inertial>
			<origin xyz="0 0 0" rpy="0 0 0"/>
			<mass value="0.40083918"/>
			<inertia ixx="0.00043534" iyy="0.00044549" izz="0.00059634" ixy="+0.00000013" iyz="+0.00000051" ixz="-0.00000002"/>
		</inertial>
	</link>
	<link name="tcp"/>



	<joint name="joint0" type="revolute">
		<parent link="link0"/>
		<child link="link1"/>
		<origin xyz="0 0 0.0775" rpy="0 0 0"/>
		<axis xyz="0 0 1"/>
		<limit effort="10" velocity="1" lower="-${175*PI/180}" upper="${175*PI/180}"/>
	</joint>

	<joint name="joint1" type="revolute">
		<parent link="link1"/>
		<child link="link2"/>
		<origin xyz="0 -0.10900000 0.22200000" rpy="${PI/2} ${PI/2} 0"/>
		<axis xyz="0 0 1"/>
		<limit effort="10" velocity="1" lower="-${175*PI/180}" upper="${175*PI/180}"/>
	</joint>

	<joint name="joint2" type="revolute">
		<parent link="link2"/>
		<child link="link3"/>
		<origin xyz="-0.45000000 +0.00000000 -0.03050000" rpy="0 0 0"/>
		<axis xyz="0 0 1"/>
		<limit effort="10" velocity="1" lower="-${175*PI/180}" upper="${175*PI/180}"/>
	</joint>

	<joint name="joint3" type="revolute">
		<parent link="link3"/>
		<child link="link4"/>
		<origin xyz="-0.26700000 +0.00000000 -0.07500000" rpy="-${PI/2} 0 ${PI/2}"/>
		<axis xyz="0 0 1"/>
		<limit effort="10" velocity="1" lower="-${175*PI/180}" upper="${175*PI/180}"/>
	</joint>

	<joint name="joint4" type="revolute">
		<parent link="link4"/>
		<child link="link5"/>
		<origin xyz="+0.00000000 -0.11400000 +0.08300000" rpy="${PI/2} ${PI/2} 0"/>
		<axis xyz="0 0 1"/>
		<limit effort="10" velocity="1" lower="-${175*PI/180}" upper="${175*PI/180}"/>
	</joint>

	<joint name="joint5" type="revolute">
		<parent link="link5"/>
		<child link="link6"/>
		<origin xyz="-0.16800000 +0.00000000 +0.06900000" rpy="-${PI/2} 0 ${PI/2}"/>
		<axis xyz="0 0 1"/>
		<limit effort="10" velocity="1" lower="-${215*PI/180}" upper="${215*PI/180}"/>
	</joint>

	<joint name="tcp" type="fixed">
		<parent link="link6"/>
		<child link="tcp"/>
		<origin xyz="0 0 0.06" rpy="0 0 0"/>
	</joint>

	<transmission name="tran0">
		<type>transmission_interface/SimpleTransmission</type>
		<joint name="joint0">
			<hardwareInterface>hardware_interface/PositionJointInterface</hardwareInterface>
		</joint>
		<actuator name="motor0">
			<hardwareInterface>hardware_interface/PositionJointInterface</hardwareInterface>
			<mechanicalReduction>1</mechanicalReduction>
		</actuator>
	</transmission>

	<transmission name="tran1">
		<type>transmission_interface/SimpleTransmission</type>
		<joint name="joint1">
			<hardwareInterface>hardware_interface/PositionJointInterface</hardwareInterface>
		</joint>
		<actuator name="motor1">
			<hardwareInterface>hardware_interface/PositionJointInterface</hardwareInterface>
			<mechanicalReduction>1</mechanicalReduction>
		</actuator>
	</transmission>

	<transmission name="tran2">
		<type>transmission_interface/SimpleTransmission</type>
		<joint name="joint2">
			<hardwareInterface>hardware_interface/PositionJointInterface</hardwareInterface>
		</joint>
		<actuator name="motor2">
			<hardwareInterface>hardware_interface/PositionJointInterface</hardwareInterface>
			<mechanicalReduction>1</mechanicalReduction>
		</actuator>
	</transmission>

	<transmission name="tran3">
		<type>transmission_interface/SimpleTransmission</type>
		<joint name="joint3">
			<hardwareInterface>hardware_interface/PositionJointInterface</hardwareInterface>
		</joint>
		<actuator name="motor3">
			<hardwareInterface>hardware_interface/PositionJointInterface</hardwareInterface>
			<mechanicalReduction>1</mechanicalReduction>
		</actuator>
	</transmission>

	<transmission name="tran4">
		<type>transmission_interface/SimpleTransmission</type>
		<joint name="joint4">
			<hardwareInterface>hardware_interface/PositionJointInterface</hardwareInterface>
		</joint>
		<actuator name="motor4">
			<hardwareInterface>hardware_interface/PositionJointInterface</hardwareInterface>
			<mechanicalReduction>1</mechanicalReduction>
		</actuator>
	</transmission>

	<transmission name="tran5">
		<type>transmission_interface/SimpleTransmission</type>
		<joint name="joint5">
			<hardwareInterface>hardware_interface/PositionJointInterface</hardwareInterface>
		</joint>
		<actuator name="motor5">
			<hardwareInterface>hardware_interface/PositionJointInterface</hardwareInterface>
			<mechanicalReduction>1</mechanicalReduction>
		</actuator>
	</transmission>

</robot>
