<?xml version="1.0" ?>
<robot name="indy7" xmlns:xacro="http://ros.org/wiki/xacro">
	<xacro:include filename="$(find indy7_description)/urdf/materials.xacro"/>
	<xacro:include filename="$(find indy7_description)/urdf/indy7.gazebo"/>

	<xacro:property name="PI" value="3.1415926535897931"/>
	<xacro:property name="indy_material" value="metal_grey"/>
	<!-- <material name="grey"> <color rgba="0.5 0.5 0.5 1"/> </material> -->

	<link name="link0">
		<visual>
			<origin xyz="0 0 0" rpy="0 0 0"/>
			<geometry>
				<mesh filename="package://indy7_description/meshes/stl/Indy7_0.stl"/>
			</geometry>
			<material name="${indy_material}"/>
		</visual>
         <collision>
            <origin xyz="0 0 0" rpy="0 0 0"/>
           	<geometry>
				<mesh filename="package://indy7_description/meshes/collision/Indy7_0.stl"/>
			</geometry>
        </collision> 
		<inertial>
			<origin xyz="0.00131966 -0.00000218 0.03212832" rpy="0 0 0"/>
			<mass value="1.67030785"/>
			<inertia ixx="+0.00661309" iyy="+0.00644765" izz="+0.00792090" ixy="+0.00000183" iyz="-0.00000027" ixz="+0.00002695"/>
		</inertial>
	</link>

	<link name="link1">
		<visual>
			<origin xyz="0 0 0" rpy="0 0 0"/>
			<geometry>
				<mesh filename="package://indy7_description/meshes/stl/Indy7_1.stl"/>
			</geometry>
			<material name="${indy_material}"/>
		</visual>
         <collision>
            <origin xyz="0 0 0" rpy="0 0 0"/>
           	<geometry>
				<mesh filename="package://indy7_description/meshes/collision/Indy7_1.stl"/>
			</geometry>
        </collision> 
		<inertial>
			<origin xyz="-0.00023749 -0.04310313 0.13245396" rpy="0 0 0"/>
			<mass value="11.44444535"/>
			<inertia ixx="+0.35065005" iyy="+0.30479800" izz="+0.06003147" ixy="+0.00011931" iyz="-0.10984447" ixz="-0.00037553"/>
		</inertial>
	</link>

	<link name="link2">
		<visual>
			<origin xyz="0 0 0" rpy="0 0 0"/>
			<geometry>
				<mesh filename="package://indy7_description/meshes/stl/Indy7_2.stl"/>
			</geometry>
			<material name="${indy_material}"/>
		</visual>
         <collision>
            <origin xyz="0 0 0" rpy="0 0 0"/>
           	<geometry>
				<mesh filename="package://indy7_description/meshes/collision/Indy7_2.stl"/>
			</geometry>
        </collision> 
		<inertial>
			<origin xyz="-0.29477536 -0.00002361 0.04762554" rpy="0 0 0"/>
			<mass value="5.84766553"/>
			<inertia ixx="+0.03599743" iyy="+0.72293306" izz="+0.70024119" ixy="-0.00004693" iyz="+0.00000176" ixz="-0.05240346"/>
		</inertial>
	</link>

	<link name="link3">
		<visual>
			<origin xyz="0 0 0" rpy="0 0 0"/>
			<geometry>
				<mesh filename="package://indy7_description/meshes/stl/Indy7_3.stl"/>
			</geometry>
			<material name="${indy_material}"/>
		</visual>
         <collision>
            <origin xyz="0 0 0" rpy="0 0 0"/>
           	<geometry>
				<mesh filename="package://indy7_description/meshes/collision/Indy7_3.stl"/>
			</geometry>
        </collision> 
		<inertial>
			<origin xyz="-0.16804016 0.00021421 -0.07000383" rpy="0 0 0"/>
			<mass value="2.68206064"/>
			<inertia ixx="+0.01617210" iyy="+0.11364055" izz="+0.10022522" ixy="-0.00011817" iyz="-0.00004371" ixz="+0.03341882"/>
		</inertial>
	</link>

	<link name="link4">
		<visual>
			<origin xyz="0 0 0" rpy="0 0 0"/>
			<geometry>
				<mesh filename="package://indy7_description/meshes/stl/Indy7_4.stl"/>
			</geometry>
			<material name="${indy_material}"/>
		</visual>
         <collision>
            <origin xyz="0 0 0" rpy="0 0 0"/>
           	<geometry>
				<mesh filename="package://indy7_description/meshes/collision/Indy7_4.stl"/>
			</geometry>
        </collision> 
		<inertial>
			<origin xyz="-0.00026847 -0.07098440 0.07649128" rpy="0 0 0"/>
			<mass value="2.12987371"/>
			<inertia ixx="+0.02798891" iyy="+0.01443076" izz="+0.01496211" ixy="+0.00003893" iyz="-0.01266296" ixz="-0.00004768"/>
		</inertial>
	</link>

	<link name="link5">
		<visual>
			<origin xyz="0 0 0" rpy="0 0 0"/>
			<geometry>
				<mesh filename="package://indy7_description/meshes/stl/Indy7_5.stl"/>
			</geometry>
			<material name="${indy_material}"/>
		</visual>
         <collision>
            <origin xyz="0 0 0" rpy="0 0 0"/>
           	<geometry>
				<mesh filename="package://indy7_description/meshes/collision/Indy7_5.stl"/>
			</geometry>
        </collision> 
		<inertial>
			<origin xyz="-0.09796232 -0.00023114 0.06445892" rpy="0 0 0"/>
			<mass value="2.22412271"/>
			<inertia ixx="+0.01105297" iyy="+0.03698291" izz="+0.02754795" ixy="+0.00005517" iyz="-0.00003740" ixz="-0.01481977"/>
		</inertial>
	</link>

	<link name="link6">
		<visual>
			<origin xyz="0 0 0" rpy="0 0 0"/>
			<geometry>
				<mesh filename="package://indy7_description/meshes/stl/Indy7_6.stl"/>
			</geometry>
			<material name="${indy_material}"/>
		</visual>
         <collision>
            <origin xyz="0 0 0" rpy="0 0 0"/>
           	<geometry>
				<mesh filename="package://indy7_description/meshes/collision/Indy7_6.stl"/>
			</geometry>
        </collision> 
		<inertial>
			<origin xyz="0.00008147 -0.00046556 0.03079097" rpy="0 0 0"/>
			<mass value="0.38254932"/>
			<inertia ixx="+0.00078982" iyy="+0.00079764" izz="+0.00058319" ixy="-0.00000034" iyz="-0.00000508" ixz="+0.00000083"/>
		</inertial>
	</link>
	<link name="tcp"/>



	<joint name="joint0" type="revolute">
		<parent link="link0"/>
		<child link="link1"/>
		<origin xyz="0 0 0.0775" rpy="0 0 0"/>
		<axis xyz="0 0 1"/>
		<limit effort="10" velocity="1" lower="-${175*PI/180}" upper="${175*PI/180}"/>
	</joint>

	<joint name="joint1" type="revolute">
		<parent link="link1"/>
		<child link="link2"/>
		<origin xyz="0 -0.10900000 0.22200000" rpy="${PI/2} ${PI/2} 0"/>
		<axis xyz="0 0 1"/>
		<limit effort="10" velocity="1" lower="-${175*PI/180}" upper="${175*PI/180}"/>
	</joint>

	<joint name="joint2" type="revolute">
		<parent link="link2"/>
		<child link="link3"/>
		<origin xyz="-0.45000000 +0.00000000 -0.03050000" rpy="0 0 0"/>
		<axis xyz="0 0 1"/>
		<limit effort="10" velocity="1" lower="-${175*PI/180}" upper="${175*PI/180}"/>
	</joint>

	<joint name="joint3" type="revolute">
		<parent link="link3"/>
		<child link="link4"/>
		<origin xyz="-0.26700000 +0.00000000 -0.07500000" rpy="-${PI/2} 0 ${PI/2}"/>
		<axis xyz="0 0 1"/>
		<limit effort="10" velocity="1" lower="-${175*PI/180}" upper="${175*PI/180}"/>
	</joint>

	<joint name="joint4" type="revolute">
		<parent link="link4"/>
		<child link="link5"/>
		<origin xyz="+0.00000000 -0.11400000 +0.08300000" rpy="${PI/2} ${PI/2} 0"/>
		<axis xyz="0 0 1"/>
		<limit effort="10" velocity="1" lower="-${175*PI/180}" upper="${175*PI/180}"/>
	</joint>

	<joint name="joint5" type="revolute">
		<parent link="link5"/>
		<child link="link6"/>
		<origin xyz="-0.16800000 +0.00000000 +0.06900000" rpy="-${PI/2} 0 ${PI/2}"/>
		<axis xyz="0 0 1"/>
		<limit effort="10" velocity="1" lower="-${215*PI/180}" upper="${215*PI/180}"/>
	</joint>

	<joint name="tcp" type="fixed">
		<parent link="link6"/>
		<child link="tcp"/>
		<origin xyz="0 0 0.06" rpy="0 0 0"/>
	</joint>

	<transmission name="tran0">
		<type>transmission_interface/SimpleTransmission</type>
		<joint name="joint0">
			<hardwareInterface>hardware_interface/PositionJointInterface</hardwareInterface>
		</joint>
		<actuator name="motor0">
			<hardwareInterface>hardware_interface/PositionJointInterface</hardwareInterface>
			<mechanicalReduction>1</mechanicalReduction>
		</actuator>
	</transmission>

	<transmission name="tran1">
		<type>transmission_interface/SimpleTransmission</type>
		<joint name="joint1">
			<hardwareInterface>hardware_interface/PositionJointInterface</hardwareInterface>
		</joint>
		<actuator name="motor1">
			<hardwareInterface>hardware_interface/PositionJointInterface</hardwareInterface>
			<mechanicalReduction>1</mechanicalReduction>
		</actuator>
	</transmission>

	<transmission name="tran2">
		<type>transmission_interface/SimpleTransmission</type>
		<joint name="joint2">
			<hardwareInterface>hardware_interface/PositionJointInterface</hardwareInterface>
		</joint>
		<actuator name="motor2">
			<hardwareInterface>hardware_interface/PositionJointInterface</hardwareInterface>
			<mechanicalReduction>1</mechanicalReduction>
		</actuator>
	</transmission>

	<transmission name="tran3">
		<type>transmission_interface/SimpleTransmission</type>
		<joint name="joint3">
			<hardwareInterface>hardware_interface/PositionJointInterface</hardwareInterface>
		</joint>
		<actuator name="motor3">
			<hardwareInterface>hardware_interface/PositionJointInterface</hardwareInterface>
			<mechanicalReduction>1</mechanicalReduction>
		</actuator>
	</transmission>

	<transmission name="tran4">
		<type>transmission_interface/SimpleTransmission</type>
		<joint name="joint4">
			<hardwareInterface>hardware_interface/PositionJointInterface</hardwareInterface>
		</joint>
		<actuator name="motor4">
			<hardwareInterface>hardware_interface/PositionJointInterface</hardwareInterface>
			<mechanicalReduction>1</mechanicalReduction>
		</actuator>
	</transmission>

	<transmission name="tran5">
		<type>transmission_interface/SimpleTransmission</type>
		<joint name="joint5">
			<hardwareInterface>hardware_interface/PositionJointInterface</hardwareInterface>
		</joint>
		<actuator name="motor5">
			<hardwareInterface>hardware_interface/PositionJointInterface</hardwareInterface>
			<mechanicalReduction>1</mechanicalReduction>
		</actuator>
	</transmission>

</robot>
