<sdf version='1.6'>
  <model name='indy7'>
    <link name='link0'>
      <pose frame=''>0 0 0 0 -0 0</pose>
      <inertial>
        <pose frame=''>0 0 0 0 -0 0</pose>
        <mass>1.59307</mass>
        <inertia>
          <ixx>0.00572623</ixx>
          <ixy>2.51e-06</ixy>
          <ixz>-0.0001138</ixz>
          <iyy>0.00558959</iyy>
          <iyz>-1.4e-07</iyz>
          <izz>0.00966674</izz>
        </inertia>
      </inertial>
      <collision name='link0_collision'>
        <pose frame=''>0 0 0 0 -0 0</pose>
        <geometry>
          <cylinder>
            <length>0.075</length>
            <radius>0.102</radius>
          </cylinder>
        </geometry>
        <surface>
          <contact>
            <ode/>
          </contact>
          <friction>
            <ode>
              <mu>0.2</mu>
              <mu2>0.2</mu2>
            </ode>
          </friction>
        </surface>
      </collision>
      <visual name='link0_visual'>
        <pose frame=''>0 0 0 0 -0 0</pose>
        <geometry>
          <mesh>
            <scale>1 1 1</scale>
            <uri>model://indy7_description/meshes/stl/Indy7_0.stl</uri>
          </mesh>
        </geometry>
        <material>
          <script>
            <name>Gazebo/White</name>
            <uri>file://media/materials/scripts/gazebo.material</uri>
          </script>
        </material>
      </visual>
      <gravity>1</gravity>
      <velocity_decay/>
    </link>
    <joint name='global' type='fixed'>
      <child>link0</child>
      <parent>world</parent>
    </joint>
    <link name='link1'>
      <pose frame=''>0 0 0.0775 0 -0 0</pose>
      <inertial>
        <pose frame=''>0 0 0 0 -0 0</pose>
        <mass>11.803</mass>
        <inertia>
          <ixx>0.154186</ixx>
          <ixy>-2.35e-06</ixy>
          <ixz>1.739e-05</ixz>
          <iyy>0.12937</iyy>
          <iyz>-0.0485427</iyz>
          <izz>0.0596441</izz>
        </inertia>
      </inertial>
      <collision name='link1_collision'>
        <pose frame=''>0 0 0.111 0 -0 0</pose>
        <geometry>
          <cylinder>
            <length>0.222</length>
            <radius>0.075</radius>
          </cylinder>
        </geometry>
        <surface>
          <contact>
            <ode/>
          </contact>
          <friction>
            <ode>
              <mu>0.2</mu>
              <mu2>0.2</mu2>
            </ode>
          </friction>
        </surface>
      </collision>
      <collision name='link1_collision_1'>
        <pose frame=''>0 -0.0545 0.222 1.5708 -0 0</pose>
        <geometry>
          <cylinder>
            <length>0.109</length>
            <radius>0.075</radius>
          </cylinder>
        </geometry>
        <surface>
          <contact>
            <ode/>
          </contact>
          <friction>
            <ode>
              <mu>0.2</mu>
              <mu2>0.2</mu2>
            </ode>
          </friction>
        </surface>
      </collision>
      <visual name='link1_visual'>
        <pose frame=''>0 0 0 0 -0 0</pose>
        <geometry>
          <mesh>
            <scale>1 1 1</scale>
            <uri>model://indy7_description/meshes/stl/Indy7_1.stl</uri>
          </mesh>
        </geometry>
        <material>
          <script>
            <name>Gazebo/White</name>
            <uri>file://media/materials/scripts/gazebo.material</uri>
          </script>
        </material>
      </visual>
      <gravity>1</gravity>
      <velocity_decay/>
    </link>
    <joint name='joint0' type='revolute'>
      <child>link1</child>
      <parent>link0</parent>
      <axis>
        <xyz>0 0 1</xyz>
        <limit>
          <lower>-3.05433</lower>
          <upper>3.05433</upper>
          <effort>10</effort>
          <velocity>1</velocity>
        </limit>
        <dynamics>
          <spring_reference>0</spring_reference>
          <spring_stiffness>0</spring_stiffness>
        </dynamics>
        <use_parent_model_frame>1</use_parent_model_frame>
      </axis>
    </joint>
    <link name='link2'>
      <pose frame=''>0 -0.109 0.2995 -1.57079 1.57079 3.14159</pose>
      <inertial>
        <pose frame=''>0 0 0 0 -0 0</pose>
        <mass>7.99292</mass>
        <inertia>
          <ixx>0.29357</ixx>
          <ixy>-4e-07</ixy>
          <ixz>1.441e-05</ixz>
          <iyy>0.280941</iyy>
          <iyz>0.0372797</iyz>
          <izz>0.0362061</izz>
        </inertia>
      </inertial>
      <collision name='link2_collision'>
        <pose frame=''>-0.225 0 0.09 1.5708 0 -1.5708</pose>
        <geometry>
          <cylinder>
            <length>0.45</length>
            <radius>0.063</radius>
          </cylinder>
        </geometry>
        <surface>
          <contact>
            <ode/>
          </contact>
          <friction>
            <ode>
              <mu>0.2</mu>
              <mu2>0.2</mu2>
            </ode>
          </friction>
        </surface>
      </collision>
      <collision name='link2_collision_1'>
        <pose frame=''>0 0 0.045 0 -0 0</pose>
        <geometry>
          <cylinder>
            <length>0.09</length>
            <radius>0.075</radius>
          </cylinder>
        </geometry>
        <surface>
          <contact>
            <ode/>
          </contact>
          <friction>
            <ode>
              <mu>0.2</mu>
              <mu2>0.2</mu2>
            </ode>
          </friction>
        </surface>
      </collision>
      <collision name='link2_collision_2'>
        <pose frame=''>-0.45 0 0.02975 0 -0 0</pose>
        <geometry>
          <cylinder>
            <length>0.1205</length>
            <radius>0.045</radius>
          </cylinder>
        </geometry>
        <surface>
          <contact>
            <ode/>
          </contact>
          <friction>
            <ode>
              <mu>0.2</mu>
              <mu2>0.2</mu2>
            </ode>
          </friction>
        </surface>
      </collision>
      <visual name='link2_visual'>
        <pose frame=''>0 0 0 0 -0 0</pose>
        <geometry>
          <mesh>
            <scale>1 1 1</scale>
            <uri>model://indy7_description/meshes/stl/Indy7_2.stl</uri>
          </mesh>
        </geometry>
        <material>
          <script>
            <name>Gazebo/White</name>
            <uri>file://media/materials/scripts/gazebo.material</uri>
          </script>
        </material>
      </visual>
      <gravity>1</gravity>
      <velocity_decay/>
    </link>
    <joint name='joint1' type='revolute'>
      <child>link2</child>
      <parent>link1</parent>
      <axis>
        <xyz>0 -1 -0</xyz>
        <limit>
          <lower>-3.05433</lower>
          <upper>3.05433</upper>
          <effort>10</effort>
          <velocity>1</velocity>
        </limit>
        <dynamics>
          <spring_reference>0</spring_reference>
          <spring_stiffness>0</spring_stiffness>
        </dynamics>
        <use_parent_model_frame>1</use_parent_model_frame>
      </axis>
    </joint>
    <link name='link3'>
      <pose frame=''>-0 -0.0785 0.7495 -1.57079 1.57079 3.14159</pose>
      <inertial>
        <pose frame=''>0 0 0 0 -0 0</pose>
        <mass>2.99134</mass>
        <inertia>
          <ixx>0.0342459</ixx>
          <ixy>1.49e-06</ixy>
          <ixz>7.24e-06</ixz>
          <iyy>0.0340602</iyy>
          <iyz>0.00186009</iyz>
          <izz>0.00450477</izz>
        </inertia>
      </inertial>
      <collision name='link3_collision'>
        <pose frame=''>-0.1335 0 -0.075 1.5708 0 -1.5708</pose>
        <geometry>
          <cylinder>
            <length>0.267</length>
            <radius>0.045</radius>
          </cylinder>
        </geometry>
        <surface>
          <contact>
            <ode/>
          </contact>
          <friction>
            <ode>
              <mu>0.2</mu>
              <mu2>0.2</mu2>
            </ode>
          </friction>
        </surface>
      </collision>
      <collision name='link3_collision_1'>
        <pose frame=''>0 0 -0.0375 0 -0 0</pose>
        <geometry>
          <cylinder>
            <length>0.075</length>
            <radius>0.045</radius>
          </cylinder>
        </geometry>
        <surface>
          <contact>
            <ode/>
          </contact>
          <friction>
            <ode>
              <mu>0.2</mu>
              <mu2>0.2</mu2>
            </ode>
          </friction>
        </surface>
      </collision>
      <visual name='link3_visual'>
        <pose frame=''>0 0 0 0 -0 0</pose>
        <geometry>
          <mesh>
            <scale>1 1 1</scale>
            <uri>model://indy7_description/meshes/stl/Indy7_3.stl</uri>
          </mesh>
        </geometry>
        <material>
          <script>
            <name>Gazebo/White</name>
            <uri>file://media/materials/scripts/gazebo.material</uri>
          </script>
        </material>
      </visual>
      <gravity>1</gravity>
      <velocity_decay/>
    </link>
    <joint name='joint2' type='revolute'>
      <child>link3</child>
      <parent>link2</parent>
      <axis>
        <xyz>0 -1 -0</xyz>
        <limit>
          <lower>-3.05433</lower>
          <upper>3.05433</upper>
          <effort>10</effort>
          <velocity>1</velocity>
        </limit>
        <dynamics>
          <spring_reference>0</spring_reference>
          <spring_stiffness>0</spring_stiffness>
        </dynamics>
        <use_parent_model_frame>1</use_parent_model_frame>
      </axis>
    </joint>
    <link name='link4'>
      <pose frame=''>-0 -0.0035 1.0165 0 -0 0</pose>
      <inertial>
        <pose frame=''>0 0 0 0 -0 0</pose>
        <mass>2.12317</mass>
        <inertia>
          <ixx>0.00670405</ixx>
          <ixy>3.75e-06</ixy>
          <ixz>1.5e-06</ixz>
          <iyy>0.00279246</iyy>
          <iyz>-0.00127967</iyz>
          <izz>0.00619341</izz>
        </inertia>
      </inertial>
      <collision name='link4_collision'>
        <pose frame=''>0 -0.057 0.083 1.5708 -0 0</pose>
        <geometry>
          <cylinder>
            <length>0.114</length>
            <radius>0.045</radius>
          </cylinder>
        </geometry>
        <surface>
          <contact>
            <ode/>
          </contact>
          <friction>
            <ode>
              <mu>0.2</mu>
              <mu2>0.2</mu2>
            </ode>
          </friction>
        </surface>
      </collision>
      <collision name='link4_collision_1'>
        <pose frame=''>0 -0.057 0.083 1.5708 -0 0</pose>
        <geometry>
          <cylinder>
            <length>0.114</length>
            <radius>0.045</radius>
          </cylinder>
        </geometry>
        <surface>
          <contact>
            <ode/>
          </contact>
          <friction>
            <ode>
              <mu>0.2</mu>
              <mu2>0.2</mu2>
            </ode>
          </friction>
        </surface>
      </collision>
      <collision name='link4_collision_2'>
        <pose frame=''>0 0 0.0415 0 -0 0</pose>
        <geometry>
          <cylinder>
            <length>0.083</length>
            <radius>0.045</radius>
          </cylinder>
        </geometry>
        <surface>
          <contact>
            <ode/>
          </contact>
          <friction>
            <ode>
              <mu>0.2</mu>
              <mu2>0.2</mu2>
            </ode>
          </friction>
        </surface>
      </collision>
      <visual name='link4_visual'>
        <pose frame=''>0 0 0 0 -0 0</pose>
        <geometry>
          <mesh>
            <scale>1 1 1</scale>
            <uri>model://indy7_description/meshes/stl/Indy7_4.stl</uri>
          </mesh>
        </geometry>
        <material>
          <script>
            <name>Gazebo/White</name>
            <uri>file://media/materials/scripts/gazebo.material</uri>
          </script>
        </material>
      </visual>
      <gravity>1</gravity>
      <velocity_decay/>
    </link>
    <joint name='joint3' type='revolute'>
      <child>link4</child>
      <parent>link3</parent>
      <axis>
        <xyz>-0 -0 1</xyz>
        <limit>
          <lower>-3.05433</lower>
          <upper>3.05433</upper>
          <effort>10</effort>
          <velocity>1</velocity>
        </limit>
        <dynamics>
          <spring_reference>0</spring_reference>
          <spring_stiffness>0</spring_stiffness>
        </dynamics>
        <use_parent_model_frame>1</use_parent_model_frame>
      </axis>
    </joint>
    <link name='link5'>
      <pose frame=''>-0 -0.1175 1.0995 -1.57079 1.57079 3.14159</pose>
      <inertial>
        <pose frame=''>0 0 0 0 -0 0</pose>
        <mass>2.28865</mass>
        <inertia>
          <ixx>0.00994891</ixx>
          <ixy>1.4e-07</ixy>
          <ixz>3.21e-06</ixz>
          <iyy>0.00978189</iyy>
          <iyz>-0.00093546</iyz>
          <izz>0.00271492</izz>
        </inertia>
      </inertial>
      <collision name='link5_collision'>
        <pose frame=''>-0.084 0 0.069 1.5708 0 -1.5708</pose>
        <geometry>
          <cylinder>
            <length>0.168</length>
            <radius>0.045</radius>
          </cylinder>
        </geometry>
        <surface>
          <contact>
            <ode/>
          </contact>
          <friction>
            <ode>
              <mu>0.2</mu>
              <mu2>0.2</mu2>
            </ode>
          </friction>
        </surface>
      </collision>
      <collision name='link5_collision_1'>
        <pose frame=''>-0 0 0.0345 0 -0 0</pose>
        <geometry>
          <cylinder>
            <length>0.069</length>
            <radius>0.045</radius>
          </cylinder>
        </geometry>
        <surface>
          <contact>
            <ode/>
          </contact>
          <friction>
            <ode>
              <mu>0.2</mu>
              <mu2>0.2</mu2>
            </ode>
          </friction>
        </surface>
      </collision>
      <visual name='link5_visual'>
        <pose frame=''>0 0 0 0 -0 0</pose>
        <geometry>
          <mesh>
            <scale>1 1 1</scale>
            <uri>model://indy7_description/meshes/stl/Indy7_5.stl</uri>
          </mesh>
        </geometry>
        <material>
          <script>
            <name>Gazebo/White</name>
            <uri>file://media/materials/scripts/gazebo.material</uri>
          </script>
        </material>
      </visual>
      <gravity>1</gravity>
      <velocity_decay/>
    </link>
    <joint name='joint4' type='revolute'>
      <child>link5</child>
      <parent>link4</parent>
      <axis>
        <xyz>0 -1 -0</xyz>
        <limit>
          <lower>-3.05433</lower>
          <upper>3.05433</upper>
          <effort>10</effort>
          <velocity>1</velocity>
        </limit>
        <dynamics>
          <spring_reference>0</spring_reference>
          <spring_stiffness>0</spring_stiffness>
        </dynamics>
        <use_parent_model_frame>1</use_parent_model_frame>
      </axis>
    </joint>
    <link name='link6'>
      <pose frame=''>-0 -0.1865 1.2675 0 -0 0</pose>
      <inertial>
        <pose frame=''>0 0 0 0 -0 0</pose>
        <mass>0.400839</mass>
        <inertia>
          <ixx>0.00043534</ixx>
          <ixy>1.3e-07</ixy>
          <ixz>-2e-08</ixz>
          <iyy>0.00044549</iyy>
          <iyz>5.1e-07</iyz>
          <izz>0.00059634</izz>
        </inertia>
      </inertial>
      <collision name='link6_collision'>
        <pose frame=''>0 0 0.03 0 -0 0</pose>
        <geometry>
          <cylinder>
            <length>0.06</length>
            <radius>0.045</radius>
          </cylinder>
        </geometry>
        <surface>
          <contact>
            <ode/>
          </contact>
          <friction>
            <ode>
              <mu>0.2</mu>
              <mu2>0.2</mu2>
            </ode>
          </friction>
        </surface>
      </collision>
      <visual name='link6_visual'>
        <pose frame=''>0 0 0 0 -0 0</pose>
        <geometry>
          <mesh>
            <scale>1 1 1</scale>
            <uri>model://indy7_description/meshes/stl/Indy7_6.stl</uri>
          </mesh>
        </geometry>
        <material>
          <script>
            <name>Gazebo/White</name>
            <uri>file://media/materials/scripts/gazebo.material</uri>
          </script>
        </material>
      </visual>
      <gravity>1</gravity>
      <velocity_decay/>
    </link>
    <joint name='joint5' type='revolute'>
      <child>link6</child>
      <parent>link5</parent>
      <axis>
        <xyz>-0 -0 1</xyz>
        <limit>
          <lower>-3.75246</lower>
          <upper>3.75246</upper>
          <effort>10</effort>
          <velocity>1</velocity>
        </limit>
        <dynamics>
          <spring_reference>0</spring_reference>
          <spring_stiffness>0</spring_stiffness>
        </dynamics>
        <use_parent_model_frame>1</use_parent_model_frame>
      </axis>
    </joint>
    <static>0</static>
    <plugin name='gazebo_ros_control' filename='libgazebo_ros_control.so'/>
  </model>
</sdf>
